2020-09-26 11:59:01,883 ERROR: Exception on /reset_password_request [POST] [in /home/void/microblog/venv/lib/python3.8/site-packages/flask/app.py:1891]
Traceback (most recent call last):
  File "/home/void/microblog/venv/lib/python3.8/site-packages/flask/app.py", line 2447, in wsgi_app
    response = self.full_dispatch_request()
  File "/home/void/microblog/venv/lib/python3.8/site-packages/flask/app.py", line 1952, in full_dispatch_request
    rv = self.handle_user_exception(e)
  File "/home/void/microblog/venv/lib/python3.8/site-packages/flask/app.py", line 1821, in handle_user_exception
    reraise(exc_type, exc_value, tb)
  File "/home/void/microblog/venv/lib/python3.8/site-packages/flask/_compat.py", line 39, in reraise
    raise value
  File "/home/void/microblog/venv/lib/python3.8/site-packages/flask/app.py", line 1950, in full_dispatch_request
    rv = self.dispatch_request()
  File "/home/void/microblog/venv/lib/python3.8/site-packages/flask/app.py", line 1936, in dispatch_request
    return self.view_functions[rule.endpoint](**req.view_args)
  File "/home/void/microblog/app/routes.py", line 173, in reset_password_request
    send_password_reset_email(user)
  File "/home/void/microblog/app/email.py", line 15, in send_password_reset_email
    send_email('[Microblog] Reset Your Password',
  File "/home/void/microblog/app/email.py", line 10, in send_email
    mail.send(msg)
  File "/home/void/microblog/venv/lib/python3.8/site-packages/flask_mail.py", line 491, in send
    with self.connect() as connection:
  File "/home/void/microblog/venv/lib/python3.8/site-packages/flask_mail.py", line 144, in __enter__
    self.host = self.configure_host()
  File "/home/void/microblog/venv/lib/python3.8/site-packages/flask_mail.py", line 158, in configure_host
    host = smtplib.SMTP(self.mail.server, self.mail.port)
  File "/usr/lib/python3.8/smtplib.py", line 253, in __init__
    (code, msg) = self.connect(host, port)
  File "/usr/lib/python3.8/smtplib.py", line 339, in connect
    self.sock = self._get_socket(host, port, self.timeout)
  File "/usr/lib/python3.8/smtplib.py", line 308, in _get_socket
    return socket.create_connection((host, port), timeout,
  File "/usr/lib/python3.8/socket.py", line 808, in create_connection
    raise err
  File "/usr/lib/python3.8/socket.py", line 796, in create_connection
    sock.connect(sa)
ConnectionRefusedError: [Errno 111] Connection refused
2020-09-26 12:02:14,220 ERROR: Exception on /reset_password/eyJ0eXAiOiJKV1QiLCJhbGciOiJIUzI1NiJ9.eyJyZXNldF9wYXNzd29yZCI6MiwiZXhwIjoxNjAxMTExNTE5LjUxNzM5M30.jKlq1KiAlQ6VXK3Vatv3hiUZGL1gs7wA1NO6UBWxVQk [POST] [in /home/void/microblog/venv/lib/python3.8/site-packages/flask/app.py:1891]
Traceback (most recent call last):
  File "/home/void/microblog/venv/lib/python3.8/site-packages/flask/app.py", line 2447, in wsgi_app
    response = self.full_dispatch_request()
  File "/home/void/microblog/venv/lib/python3.8/site-packages/flask/app.py", line 1952, in full_dispatch_request
    rv = self.handle_user_exception(e)
  File "/home/void/microblog/venv/lib/python3.8/site-packages/flask/app.py", line 1821, in handle_user_exception
    reraise(exc_type, exc_value, tb)
  File "/home/void/microblog/venv/lib/python3.8/site-packages/flask/_compat.py", line 39, in reraise
    raise value
  File "/home/void/microblog/venv/lib/python3.8/site-packages/flask/app.py", line 1950, in full_dispatch_request
    rv = self.dispatch_request()
  File "/home/void/microblog/venv/lib/python3.8/site-packages/flask/app.py", line 1936, in dispatch_request
    return self.view_functions[rule.endpoint](**req.view_args)
  File "/home/void/microblog/app/routes.py", line 192, in reset_password
    return redirect(url_for('logn'))
  File "/home/void/microblog/venv/lib/python3.8/site-packages/flask/helpers.py", line 370, in url_for
    return appctx.app.handle_url_build_error(error, endpoint, values)
  File "/home/void/microblog/venv/lib/python3.8/site-packages/flask/app.py", line 2216, in handle_url_build_error
    reraise(exc_type, exc_value, tb)
  File "/home/void/microblog/venv/lib/python3.8/site-packages/flask/_compat.py", line 39, in reraise
    raise value
  File "/home/void/microblog/venv/lib/python3.8/site-packages/flask/helpers.py", line 357, in url_for
    rv = url_adapter.build(
  File "/home/void/microblog/venv/lib/python3.8/site-packages/werkzeug/routing.py", line 2179, in build
    raise BuildError(endpoint, values, method, self)
werkzeug.routing.BuildError: Could not build url for endpoint 'logn'. Did you mean 'login' instead?
2020-09-26 12:02:46,726 INFO: Microblog startup [in /home/void/microblog/app/__init__.py:47]
2020-09-26 12:08:37,717 INFO: Microblog startup [in /home/void/microblog/app/__init__.py:47]
2020-09-26 12:44:40,434 INFO: Microblog startup [in /home/void/microblog/app/__init__.py:49]
2020-09-26 12:47:44,452 INFO: Microblog startup [in /home/void/microblog/app/__init__.py:49]
2020-09-26 13:01:37,453 INFO: Microblog startup [in /home/void/microblog/app/__init__.py:51]
2020-09-26 13:20:05,137 INFO: Microblog startup [in /home/void/microblog/app/__init__.py:53]
2020-09-26 13:46:22,752 INFO: Microblog startup [in /home/void/microblog/app/__init__.py:53]
2020-09-26 13:47:51,830 INFO: Microblog startup [in /home/void/microblog/app/__init__.py:53]
2020-09-26 13:51:52,949 INFO: Microblog startup [in /home/void/microblog/app/__init__.py:53]
2020-09-26 13:54:41,201 INFO: Microblog startup [in /home/void/microblog/app/__init__.py:53]
2020-09-26 13:55:02,640 INFO: Microblog startup [in /home/void/microblog/app/__init__.py:53]
2020-09-26 14:04:19,459 INFO: Microblog startup [in /home/void/microblog/app/__init__.py:53]
2020-09-26 14:04:30,375 INFO: Microblog startup [in /home/void/microblog/app/__init__.py:53]
2020-09-26 14:06:59,333 INFO: Microblog startup [in /home/void/microblog/app/__init__.py:53]
2020-09-26 14:51:53,592 INFO: Microblog startup [in /home/void/microblog/app/__init__.py:53]
2020-09-26 14:52:10,284 ERROR: Exception on /unfollow/Davis [POST] [in /home/void/microblog/venv/lib/python3.8/site-packages/flask/app.py:1891]
Traceback (most recent call last):
  File "/home/void/microblog/venv/lib/python3.8/site-packages/flask/app.py", line 2447, in wsgi_app
    response = self.full_dispatch_request()
  File "/home/void/microblog/venv/lib/python3.8/site-packages/flask/app.py", line 1952, in full_dispatch_request
    rv = self.handle_user_exception(e)
  File "/home/void/microblog/venv/lib/python3.8/site-packages/flask/app.py", line 1821, in handle_user_exception
    reraise(exc_type, exc_value, tb)
  File "/home/void/microblog/venv/lib/python3.8/site-packages/flask/_compat.py", line 39, in reraise
    raise value
  File "/home/void/microblog/venv/lib/python3.8/site-packages/flask/app.py", line 1950, in full_dispatch_request
    rv = self.dispatch_request()
  File "/home/void/microblog/venv/lib/python3.8/site-packages/flask/app.py", line 1936, in dispatch_request
    return self.view_functions[rule.endpoint](**req.view_args)
  File "/home/void/microblog/venv/lib/python3.8/site-packages/flask_login/utils.py", line 272, in decorated_view
    return func(*args, **kwargs)
  File "/home/void/microblog/app/routes.py", line 149, in unfollow
    flash(_('You are not following {}.', format(username)))
  File "/home/void/microblog/venv/lib/python3.8/site-packages/flask_babel/__init__.py", line 689, in gettext
    return get_domain().gettext(*args, **kwargs)
TypeError: gettext() takes 2 positional arguments but 3 were given
2020-09-26 14:54:23,212 INFO: Microblog startup [in /home/void/microblog/app/__init__.py:53]
2020-09-26 15:00:17,615 INFO: Microblog startup [in /home/void/microblog/app/__init__.py:53]
2020-09-26 15:00:22,984 INFO: Microblog startup [in /home/void/microblog/app/__init__.py:53]
2020-09-26 15:29:52,599 INFO: Microblog startup [in /home/void/microblog/app/__init__.py:53]
2020-09-26 15:31:45,588 INFO: Microblog startup [in /home/void/microblog/app/__init__.py:53]
2020-09-26 15:33:53,075 INFO: Microblog startup [in /home/void/microblog/app/__init__.py:53]
2020-09-26 15:34:59,252 INFO: Microblog startup [in /home/void/microblog/app/__init__.py:53]
2020-09-26 15:36:36,360 INFO: Microblog startup [in /home/void/microblog/app/__init__.py:53]
2020-09-26 15:37:38,809 INFO: Microblog startup [in /home/void/microblog/app/__init__.py:53]
2020-09-26 15:43:14,570 INFO: Microblog startup [in /home/void/microblog/app/__init__.py:53]
2020-09-26 17:10:39,592 INFO: Microblog startup [in /home/void/microblog/app/__init__.py:53]
2020-09-26 17:10:46,072 INFO: Microblog startup [in /home/void/microblog/app/__init__.py:53]
2020-09-26 17:10:50,844 INFO: Microblog startup [in /home/void/microblog/app/__init__.py:53]
2020-09-26 17:15:19,862 INFO: Microblog startup [in /home/void/microblog/app/__init__.py:53]
2020-09-26 17:27:52,276 INFO: Microblog startup [in /home/void/microblog/app/__init__.py:53]
